<?xml version='1.0'?>

<robot name="rosbot" 
  xmlns:xacro="http://www.ros.org/wiki/xacro">

  <xacro:arg name="robot_namespace" default=""/>

  <xacro:property name="cameraSize" value="0.05"/>
  <xacro:property name="cameraMass" value="0.1"/>
  <xacro:property name="namespace" value="$(arg robot_namespace)" />

  <xacro:include filename="$(find patrolling_robot)/urdf/rosbot.gazebo" />
  <xacro:include filename="$(find patrolling_robot)/urdf/materials.xacro" />
  <xacro:include filename="$(find patrolling_robot)/urdf/macros.xacro" />

  <!-- macro for cylinder inertia -->
  <xacro:macro name="cylinder_inertia" params="mass r l o_rpy"> 
    <inertial>
      <mass value="${mass}" />
      <origin rpy="${o_rpy}" xyz="0 0 0"/>  
      <inertia ixx="${mass*(3*r*r+l*l)/12}" ixy = "0" ixz = "0" iyy="${mass*(3*r*r+l*l)/12}" iyz = "0" izz="${mass*(r*r)/2}" /> 
    </inertial>
  </xacro:macro>

  <!-- revolute joint arm link macro -->
  <xacro:macro name="joint_link" params="name ax lower upper parent child origin_xyz">
    <joint name="${name}" type="revolute">
      <axis xyz="${ax}"/>
      <limit effort="1000.0" lower="${lower}" upper="${upper}" velocity="0.2"/>
      <origin rpy="0 0 0" xyz="${origin_xyz}"/>
      <parent link="${parent}"/>
      <child link="${child}"/>
      <joint_properties damping="5.0" friction="1.0"/>
    </joint>
  </xacro:macro>


  <link name='base_link'>
    <pose>0 0 0.1 0 0 0</pose>

    <inertial>
      <mass value="5"/>
      <origin xyz="0 0 0.04" rpy=" 0 0 0"/>
      <inertia 
      ixx="0.01" ixy="0.01" ixz="0" 
      iyy="0.01" iyz="0.01" 
      izz="0.01" 
      />
    </inertial>

    <collision name='collision'>
      <origin xyz="0 0 0.02" rpy="0 0 0"/>
      <geometry>
        <box size="0.20 0.15 0.04"/>
      </geometry>
    </collision>

    <visual name='base_link_visual'>
      <origin xyz="0 0 -0.02" rpy=" 1.5707 0 1.5707"/>
      <geometry>
        <mesh filename="package://patrolling_robot/meshes/box.dae" scale="0.001 0.001 0.001" />
      </geometry>
    </visual>

  </link>

  <joint name="top_joint" type="fixed">
    <axis xyz="0 1 0" />
    <origin xyz="0 0 0" rpy="0 0 0"/>
    <parent link="base_link"/>
    <child link="top"/>
  </joint>

  <link name='top'>
    <pose>0 0 0 0 0 0</pose>

    <inertial>
      <mass value="0.01"/>
      <origin xyz="0 0 0.055" rpy=" 0 0 0"/>
      <inertia 
      ixx="0.0" ixy="0" ixz="0" 
      iyy="0.0" iyz="0" 
      izz="0.0" 
      />
    </inertial>
    <visual name='top'>
      <origin xyz="0 0 0.055" rpy=" 1.5707 0 1.5707"/>
      <geometry>
        <mesh filename="package://patrolling_robot/meshes/upper.dae" scale="0.001 0.001 0.001" />
      </geometry>
    </visual>
  </link>

  <link name="front_left_wheel">
    <collision name="collision">
      <origin xyz="0 0 0" rpy="0 0 1.5707"/>
      <geometry>
        <mesh filename="package://patrolling_robot/meshes/wheel.dae" scale="0.001 0.001 0.001" />
      </geometry>
      <surface>
        <friction>
          <ode>
            <mu>10</mu>
            <mu2>10</mu2>
          </ode>
        </friction>
      </surface>
    </collision>
    <visual name="front_left_wheel_visual">
      <origin xyz="0 0 0" rpy="0 0 1.5707"/>
      <geometry>
        <mesh filename="package://patrolling_robot/meshes/wheel.dae" scale="0.001 0.001 0.001" />
      </geometry>
    </visual>
    <inertial>
      <origin xyz="0 0 0" rpy="0 1.5707 1.5707"/>
      <mass value="0.5"/>
      <inertia 
      ixx="0.001" ixy="0.0" ixz="0.0" 
      iyy="0.001" iyz="0.0" 
      izz="0.001"/>
    </inertial>
  </link>

  <link name="front_right_wheel">
    <collision name="collision">
      <origin xyz="0 0 0" rpy="0 0 -1.5707"/>
      <geometry>
        <mesh filename="package://patrolling_robot/meshes/wheel.dae" scale="0.001 0.001 0.001" />
      </geometry>
      <surface>
        <friction>
          <ode>
            <mu>10</mu>
            <mu2>10</mu2>
          </ode>
        </friction>
      </surface>
    </collision>
    <visual name="front_right_wheel_visual">
      <origin xyz="0 0 0" rpy="0 0 -1.5707"/>
      <geometry>
        <mesh filename="package://patrolling_robot/meshes/wheel.dae" scale="0.001 0.001 0.001" />
      </geometry>
    </visual>
    <inertial>
      <origin xyz="0 0 0" rpy="0 1.5707 1.5707"/>
      <mass value="0.5"/>
      <inertia 
      ixx="0.001" ixy="0.0" ixz="0.0" 
      iyy="0.001" iyz="0.0" 
      izz="0.001"/>
    </inertial>
  </link>

  <link name="rear_left_wheel">
    <collision name="collision">
      <origin xyz="0 0 0" rpy="0 0 1.5707"/>
      <geometry>
        <mesh filename="package://patrolling_robot/meshes/wheel.dae" scale="0.001 0.001 0.001" />
      </geometry>
      <surface>
        <friction>
          <ode>
            <mu>10</mu>
            <mu2>10</mu2>
          </ode>
        </friction>
      </surface>
    </collision>
    <visual name="rear_left_wheel_visual">
      <origin xyz="0 0 0" rpy="0 0 1.5707"/>
      <geometry>
        <mesh filename="package://patrolling_robot/meshes/wheel.dae" scale="0.001 0.001 0.001" />
      </geometry>
    </visual>
    <inertial>
      <origin xyz="0 0 0" rpy="0 1.5707 1.5707"/>
      <mass value="0.5"/>
      <inertia 
      ixx="0.001" ixy="0.0" ixz="0.0" 
      iyy="0.001" iyz="0.0" 
      izz="0.001"/>
    </inertial>
  </link>

  <link name="rear_right_wheel">
    <collision name="collision">
      <origin xyz="0 0 0" rpy="0 0 -1.5707"/>
      <geometry>
        <mesh filename="package://patrolling_robot/meshes/wheel.dae" scale="0.001 0.001 0.001" />
      </geometry>
      <surface>
        <friction>
          <ode>
            <mu>10</mu>
            <mu2>10</mu2>
          </ode>
        </friction>
      </surface>
    </collision>
    <visual name="rear_right_wheel_visual">
      <origin xyz="0 0 0" rpy="0 0 -1.5707"/>
      <geometry>
        <mesh filename="package://patrolling_robot/meshes/wheel.dae" scale="0.001 0.001 0.001" />
      </geometry>
    </visual>
    <inertial>
      <origin xyz="0 0 0" rpy="0 1.5707 1.5707"/>
      <mass value="0.5"/>
      <inertia 
      ixx="0.001" ixy="0.0" ixz="0.0" 
      iyy="0.001" iyz="0.0" 
      izz="0.001"/>
    </inertial>
  </link>


  <joint type="continuous" name="front_left_wheel_hinge">
    <origin xyz="0.05 0.11 0" rpy="0 0 0"/>
    <child link="front_left_wheel"/>
    <parent link="base_link"/>
    <axis xyz="0 1 0" rpy="0 0 0"/>
    <limit effort="1" velocity="10"/>
    <joint_properties damping="5.0" friction="1.0"/>
  </joint>

  <transmission name="front_left_wheel_trans" type="SimpleTransmission">
    <type>transmission_interface/SimpleTransmission</type>
    <actuator name="front_left_wheel_motor">
      <mechanicalReduction>1</mechanicalReduction>
    </actuator>
    <joint name="front_left_wheel_hinge">
      <hardwareInterface>hardware_interface/EffortJointInterface</hardwareInterface>
    </joint>
  </transmission>

  <joint type="continuous" name="front_right_wheel_hinge">
    <origin xyz="0.05 -0.11 0" rpy="0 0 0"/>
    <child link="front_right_wheel"/>
    <parent link="base_link"/>
    <axis xyz="0 1 0" rpy="0 0 0"/>
    <limit effort="1" velocity="10"/>
    <joint_properties damping="5.0" friction="1.0"/>
  </joint>

  <transmission name="front_right_wheel_trans" type="SimpleTransmission">
    <type>transmission_interface/SimpleTransmission</type>
    <actuator name="front_right_wheel_motor">
      <mechanicalReduction>1</mechanicalReduction>
    </actuator>
    <joint name="front_right_wheel_hinge">
      <hardwareInterface>hardware_interface/EffortJointInterface</hardwareInterface>
    </joint>
  </transmission>

  <joint type="continuous" name="rear_left_wheel_hinge">
    <origin xyz="-0.055 0.11 0" rpy="0 0 0"/>
    <child link="rear_left_wheel"/>
    <parent link="base_link"/>
    <axis xyz="0 1 0" rpy="0 0 0"/>
    <limit effort="1" velocity="10"/>
    <joint_properties damping="5.0" friction="1.0"/>
  </joint>

  <transmission name="rear_left_wheel_trans" type="SimpleTransmission">
    <type>transmission_interface/SimpleTransmission</type>
    <actuator name="rear_left_wheel_motor">
      <mechanicalReduction>1</mechanicalReduction>
    </actuator>
    <joint name="rear_left_wheel_hinge">
      <hardwareInterface>hardware_interface/EffortJointInterface</hardwareInterface>
    </joint>
  </transmission>

  <joint type="continuous" name="rear_right_wheel_hinge">
    <origin xyz="-0.055 -0.11 0" rpy="0 0 0"/>
    <child link="rear_right_wheel"/>
    <parent link="base_link"/>
    <axis xyz="0 1 0" rpy="0 0 0"/>
    <limit effort="1" velocity="10"/>
    <joint_properties damping="5.0" friction="1.0"/>
  </joint>

  <transmission name="rear_right_wheel_trans" type="SimpleTransmission">
    <type>transmission_interface/SimpleTransmission</type>
    <actuator name="rear_right_wheel_motor">
      <mechanicalReduction>1</mechanicalReduction>
    </actuator>
    <joint name="rear_right_wheel_hinge">
      <hardwareInterface>hardware_interface/EffortJointInterface</hardwareInterface>
    </joint>
  </transmission>

  <!-- joints and links to move the camera, allowing yawl and pitch motions-->
  <xacro:joint_link name="yawl_joint" ax="0 0 1" lower="-3.14" upper="3.14" parent="base_link" child="yawl_link" origin_xyz="-0.038 0 0.127"  />

  <link name="yawl_link">
    <collision>
      <origin xyz="0 0 0" rpy="0 0 0"/>
      <geometry>
        <cylinder length="0.01" radius="0.025"/>
      </geometry>
    </collision>

    <visual>
      <origin xyz="0 0 0" rpy="0 0 0"/>
      <geometry>
        <cylinder length="0.01" radius="0.025"/>
      </geometry>
    </visual>

    <xacro:cylinder_inertia mass="0.2" r="0.02" l="0.001" o_rpy="0 0 0"/>
  </link>

  <xacro:joint_link name="pitch_joint" ax="0 1 0" lower="-0.5" upper="0.5" parent="yawl_link" child="pitch_link" origin_xyz="0 0 0.01"  />

  <link name="pitch_link">
    <collision>
      <origin xyz="0 0 0" rpy="0 0 0"/>
      <geometry>
        <box size="0.06 0.06 0.01"/>
      </geometry>
    </collision>

    <visual>
      <origin xyz="0 0 0" rpy="0 0 0"/>
      <geometry>
        <box size="0.06 0.06 0.01"/>
      </geometry>
    </visual>

    <inertial>
      <mass value="1e-5" />
      <origin xyz="0 0 0" rpy="0 0 0"/>
      <inertia ixx="0" ixy="0" ixz="0" iyy="0" iyz="0" izz="0" />
    </inertial>
  </link>

  <transmission name="yawl_joint_trans">
      <type>transmission_interface/SimpleTransmission</type>
      <joint name="yawl_joint">
        <hardwareInterface>hardware_interface/EffortJointInterface</hardwareInterface>
      </joint>
      <actuator name="motor1">
        <hardwareInterface>hardware_interface/EffortJointInterface</hardwareInterface>
        <mechanicalInterface>1</mechanicalInterface>
      </actuator>
    </transmission>

    <transmission name="pitch_joint_trans">
      <type>transmission_interface/SimpleTransmission</type>
      <joint name="pitch_joint">
        <hardwareInterface>hardware_interface/EffortJointInterface</hardwareInterface>
      </joint>
      <actuator name="motor2">
        <hardwareInterface>hardware_interface/EffortJointInterface</hardwareInterface>
        <mechanicalInterface>1</mechanicalInterface>
      </actuator>
    </transmission>

  <!-- Orbbec Astra RGBD Camera -->
  <joint name="astra_joint" type="fixed">
    <axis xyz="0 0 0" />
    <origin xyz="0.03 0 0.064" rpy="0 0 0"/>
    <parent link="pitch_link"/>
    <child link="camera_link"/>
  </joint>

  <link name="camera_link">
    <collision>
      <origin xyz="0.02 0 0" rpy="0 0 0"/>
      <geometry>
        <box size="0.001 0.001 0.001"/>
      </geometry>
    </collision>

    <visual>
      <origin xyz="-0.01 0 -0.03" rpy="1.5707 0 1.5707"/>
      <geometry>
        <mesh filename="package://patrolling_robot/meshes/astra.dae" scale="0.001 0.001 0.001" />
      </geometry>
    </visual>

    <inertial>
      <mass value="1e-5" />
      <origin xyz="0 0 0" rpy="0 0 0"/>
      <inertia ixx="0" ixy="0" ixz="0" iyy="0" iyz="0" izz="0" />
    </inertial>
  </link>

  <joint name="camera_optical_joint" type="fixed">
    <origin xyz="0 0 0" rpy="${-pi/2} 0 ${-pi/2}"/>
    <parent link="camera_link"/>
    <child link="camera_rgb_frame"/>
  </joint>

  <link name="camera_rgb_frame">
  </link>

  <joint name="camera_depth_joint" type="fixed">
    <origin xyz="0 0 0" rpy="${-pi/2} 0 ${-pi/2}"/>
    <parent link="camera_link"/>
    <child link="camera_depth_frame"/>
  </joint>

  <link name="camera_depth_frame">
  </link>

  <joint name="rplidar_joint" type="fixed">
    <axis xyz="0 1 0" />
    <origin xyz="0.02 0 0" rpy="0 0 3.14"/>
    <parent link="base_link"/>
    <child link="laser"/>
  </joint>

  <!-- rplidar Laser -->
  <link name="laser">
    <collision>
      <origin xyz="0 0 0.058" rpy="1.5707 0 4.71"/>
      <geometry>
        <mesh filename="package://patrolling_robot/meshes/rplidar.dae" scale="0.001 0.001 0.001" />
      </geometry>
    </collision>

    <visual>
      <origin xyz="0 0 0.058" rpy="1.5707 0 4.71"/>
      <geometry>
        <mesh filename="package://patrolling_robot/meshes/rplidar.dae" scale="0.001 0.001 0.001" />
      </geometry>
    </visual>

    <inertial>
      <mass value="1e-5" />
      <origin xyz="0 0 0.058" rpy="1.5707 0 4.71"/>
      <inertia ixx="0" ixy="0" ixz="0" iyy="0" iyz="0" izz="0" />
    </inertial>
  </link>

  <joint name="range_fl_joint" type="fixed">
    <axis xyz="0 1 0" />
    <origin xyz="0.1 0.05 0.01" rpy="0 0 0.13 "/>
    <parent link="base_link"/>
    <child link="range_fl"/>
  </joint>
  <link name="range_fl"></link>

  <joint name="range_fr_joint" type="fixed">
    <axis xyz="0 1 0" />
    <origin xyz="0.1 -0.05 0.01" rpy="0 0 -0.13 "/>
    <parent link="base_link"/>
    <child link="range_fr"/>
  </joint>
  <link name="range_fr"></link>

  <joint name="range_rl_joint" type="fixed">
    <axis xyz="0 1 0" />
    <origin xyz="-0.1 0.05 0.01" rpy="0 0 3.01 "/>
    <parent link="base_link"/>
    <child link="range_rl"/>
  </joint>
  <link name="range_rl"></link>

  <joint name="range_rr_joint" type="fixed">
    <axis xyz="0 1 0" />
    <origin xyz="-0.1 -0.05 0.01" rpy="0 0 3.27 "/>
    <parent link="base_link"/>
    <child link="range_rr"/>
  </joint>
  <link name="range_rr"></link>

</robot>
